<?xml version="1.0" encoding="utf-8"?>
<!-- This URDF was automatically created by SolidWorks to URDF Exporter! Originally created by Stephen Brawner (brawner@gmail.com) 
     Commit Version: 1.6.0-1-g15f4949  Build Version: 1.6.7594.29634
     For more information, please see http://wiki.ros.org/sw_urdf_exporter -->
<robot
  name="area55">
  <link
    name="base_link">
    <inertial>
      <origin
        xyz="-0.065009 0.00037769 0.034384"
        rpy="0 0 0" />
      <mass
        value="5" />
      <inertia
        ixx="0.22816"
        ixy="-0.0007158"
        ixz="-0.0020332"
        iyy="0.13923"
        iyz="3.5333E-05"
        izz="0.3473" />
    </inertial>
    <visual>
      <origin
        xyz="0 0 0"
        rpy="0 0 0" />
      <geometry>
        <mesh
          filename="package://area55/meshes/base_link.STL" />
      </geometry>
      <material
        name="">
        <color
          rgba="0.79216 0.81961 0.93333 1" />
      </material>
    </visual>
    <collision>
      <origin
        xyz="0 0 0"
        rpy="0 0 0" />
      <geometry>
        <mesh
          filename="package://area55/meshes/base_link.STL" />
      </geometry>
    </collision>
  </link>
  <link
    name="L_link">
    <inertial>
      <origin
        xyz="0.02 0 -1.3878E-17"
        rpy="0 0 0" />
      <mass
        value="3" />
      <inertia
        ixx="0.00086187"
        ixy="-7.0046E-20"
        ixz="-8.4808E-20"
        iyy="0.00047589"
        iyz="-1.2197E-19"
        izz="0.00047589" />
    </inertial>
    <visual>
      <origin
        xyz="0 0 0"
        rpy="0 0 0" />
      <geometry>
        <mesh
          filename="package://area55/meshes/L_link.STL" />
      </geometry>
      <material
        name="">
        <color
          rgba="0.79216 0.81961 0.93333 1" />
      </material>
    </visual>
    <collision>
      <origin
        xyz="0 0 0"
        rpy="0 0 0" />
      <geometry>
        <mesh
          filename="package://area55/meshes/L_link.STL" />
      </geometry>
    </collision>
  </link>
  <joint
    name="L_joint"
    type="continuous">
    <origin
      xyz="0.082504 0.205 0.02"
      rpy="2.5634 0 1.5708" />
    <parent
      link="base_link" />
    <child
      link="L_link" />
    <axis
      xyz="1 0 0" />
  </joint>
  <link
    name="R_link">
    <inertial>
      <origin
        xyz="-0.02 0 0"
        rpy="0 0 0" />
      <mass
        value="3" />
      <inertia
        ixx="0.00086187"
        ixy="-6.3145E-20"
        ixz="-8.8244E-20"
        iyy="0.00047589"
        iyz="1.3553E-20"
        izz="0.00047589" />
    </inertial>
    <visual>
      <origin
        xyz="0 0 0"
        rpy="0 0 0" />
      <geometry>
        <mesh
          filename="package://area55/meshes/R_link.STL" />
      </geometry>
      <material
        name="">
        <color
          rgba="0.79216 0.81961 0.93333 1" />
      </material>
    </visual>
    <collision>
      <origin
        xyz="0 0 0"
        rpy="0 0 0" />
      <geometry>
        <mesh
          filename="package://area55/meshes/R_link.STL" />
      </geometry>
    </collision>
  </link>
  <joint
    name="R_joint"
    type="continuous">
    <origin
      xyz="0.082504 -0.205 0.02"
      rpy="2.2586 0 1.5708" />
    <parent
      link="base_link" />
    <child
      link="R_link" />
    <axis
      xyz="1 0 0" />
  </joint>
  <link
    name="castor_link">
    <inertial>
      <origin
        xyz="0 2.7756E-17 2.7756E-17"
        rpy="0 0 0" />
      <mass
        value="1" />
      <inertia
        ixx="0.00012425"
        ixy="0"
        ixz="-6.7763E-21"
        iyy="0.00012425"
        iyz="0"
        izz="0.00012425" />
    </inertial>
    <visual>
      <origin
        xyz="0 0 0"
        rpy="0 0 0" />
      <geometry>
        <mesh
          filename="package://area55/meshes/castor_link.STL" />
      </geometry>
      <material
        name="">
        <color
          rgba="0.79216 0.81961 0.93333 1" />
      </material>
    </visual>
    <collision>
      <origin
        xyz="0 0 0"
        rpy="0 0 0" />
      <geometry>
        <mesh
          filename="package://area55/meshes/castor_link.STL" />
      </geometry>
    </collision>
  </link>
  <joint
    name="castor_joint"
    type="continuous">
    <origin
      xyz="-0.25 0 0"
      rpy="1.9804 0.71349 -0.61193" />
    <parent
      link="base_link" />
    <child
      link="castor_link" />
    <axis
      xyz="0.43433 0.67086 0.60109" />
    <dynamics
      damping="0"
      friction="0" />
  </joint>

  <gazebo>

    <plugin filename="libgazebo_ros_diff_drive.so" name="differential_drive_controller">

      <legacyMode>false</legacyMode>

      <alwaysOn>true</alwaysOn>

      <updateRate>20</updateRate>

      <leftJoint>L_joint</leftJoint>

      <rightJoint>R_joint</rightJoint>

      <wheelSeparation>0.41</wheelSeparation>

      <wheelDiameter>0.13</wheelDiameter>

      <torque>5</torque>

      <commandTopic>cmd_vel</commandTopic>

      <odometryTopic>odom</odometryTopic>

      <odometryFrame>odom</odometryFrame>

      <robotBaseFrame>base_link</robotBaseFrame>

    </plugin>

  </gazebo>

  <link
    name="grip_link">
    <inertial>
      <origin
        xyz="-0.22027 -0.01404 0.072882"
        rpy="0 0 0" />
      <mass
        value="0.8" />
      <inertia
        ixx="0.00026962"
        ixy="0.0002465"
        ixz="-0.00021898"
        iyy="0.00629"
        iyz="5.9108E-05"
        izz="0.0064174" />
    </inertial>
    <visual>
      <origin
        xyz="0 0 0"
        rpy="0 0 0" />
      <geometry>
        <mesh
          filename="package://area55/meshes/grip_link.STL" />
      </geometry>
      <material
        name="">
        <color
          rgba="0.79216 0.81961 0.93333 1" />
      </material>
    </visual>
    <collision>
      <origin
        xyz="0 0 0"
        rpy="0 0 0" />
      <geometry>
        <mesh
          filename="package://area55/meshes/grip_link.STL" />
      </geometry>
    </collision>
  </link>
  <joint
    name="grip_joint"
    type="revolute">
    <origin
      xyz="0.181 0.22 0.02"
      rpy="1.5708 0.0033621 1.5708" />
    <parent
      link="base_link" />
    <child
      link="grip_link" />
    <axis
      xyz="0 0 -1" />
    <limit
      lower="0"
      upper="1.7"
      effort="3000"
      velocity="0.8" />
    <dynamics
      damping="0"
      friction="0" />
  </joint>



  <link
    name="scan_link">
    <inertial>
      <origin
        xyz="-5.5511E-17 0.025 -6.9389E-18"
        rpy="0 0 0" />
      <mass
        value="0.1" />
      <inertia
        ixx="5.2083E-05"
        ixy="4.9287E-21"
        ixz="-2.9023E-21"
        iyy="5.2083E-05"
        iyz="6.6042E-21"
        izz="5.2083E-05" />
    </inertial>
    <visual>
      <origin
        xyz="0 0 0"
        rpy="0 0 0" />
      <geometry>
        <box size="0.05 0.05 0.05"/>
      </geometry>
      <material
        name="">
        <color
          rgba="2 1 0.93333 1" />
      </material>
    </visual>
    <collision>
      <origin
        xyz="0 0 0"
        rpy="0 0 0" />
      <geometry>
        <mesh
          filename="package://area55/meshes/scan_link.STL" />
      </geometry>
    </collision>
  </link>
  <joint
    name="scan_joint"
    type="fixed">
    <origin
      xyz="-0.20534 -0.0230 0.105"
      rpy="3.1356 -1.5708 -1.5708" />
    <parent
      link="grip_link" />
    <child
      link="scan_link" />
    <axis
      xyz="0 0 0" />
  </joint>
  <link
    name="photo_link">
    <inertial>
      <origin
        xyz="0 0.025 -5.9292E-19"
        rpy="0 0 0" />
      <mass
        value="0.1" />
      <inertia
        ixx="5.2083E-05"
        ixy="-7.5668E-22"
        ixz="-6.2116E-22"
        iyy="5.2083E-05"
        iyz="1.4117E-21"
        izz="5.2083E-05" />
    </inertial>
    <visual>
      <origin
        xyz="0 0 0"
        rpy="0 0 0" />
      <geometry>
        <box size="0.05 0.05 0.05"/>
      </geometry>
      <material
        name="">
        <color
          rgba="0.79216 0.81961 0.93333 1" />
      </material>
    </visual>
    <collision>
      <origin
        xyz="0 0 0"
        rpy="0 0 0" />
      <geometry>
        <mesh
          filename="package://area55/meshes/photo_link.STL" />
      </geometry>
    </collision>
  </link>
  <joint
    name="photo_joint"
    type="fixed">
    <origin
      xyz="-0.25 0 0.3"
      rpy="1.5708 0 0" />
    <parent
      link="base_link" />
    <child
      link="photo_link" />
    <axis
      xyz="0 0 0" />
  </joint>

  <gazebo>
    <plugin name="gazebo_ros_control" filename="libgazebo_ros_control.so">
      <robotNamespace>/area55</robotNamespace>
      <robotSimType>gazebo_ros_control/DefaultRobotHWSim</robotSimType>
      <legacyModeNS>true</legacyModeNS>
    </plugin>
  </gazebo>

  <!-- transmission -->
  <transmission name="base_to_second_trans">
    <type>transmission_interface/SimpleTransmission</type>
    <actuator name="motor1">
      <mechanicalReduction>1</mechanicalReduction>
    </actuator>
    <joint name="grip_joint">
      <hardwareInterface>PositionJointInterface</hardwareInterface>
    </joint>
  </transmission>


  <gazebo reference="photo_link">
    <sensor type="camera" name="camera1">
      <update_rate>30.0</update_rate>
      <camera name="head">
        <horizontal_fov>1.3962634</horizontal_fov>
        <image>
          <width>800</width>
          <height>800</height>
          <format>R8G8B8</format>
        </image>
        <clip>
          <near>0.02</near>
          <far>300</far>
        </clip>
        <noise>
          <type>gaussian</type>
          <!-- Noise is sampled independently per pixel on each frame.
               That pixel's noise value is added to each of its color
               channels, which at that point lie in the range [0,1]. -->
          <mean>0.0</mean>
          <stddev>0.007</stddev>
        </noise>
      </camera>
      <plugin name="camera_controller" filename="libgazebo_ros_camera.so">
        <alwaysOn>true</alwaysOn>
        <updateRate>0.0</updateRate>
        <cameraName>robot/camera1</cameraName>
        <imageTopicName>image_raw</imageTopicName>
        <cameraInfoTopicName>camera_info</cameraInfoTopicName>
        <frameName>photo_link</frameName>
        <hackBaseline>0.07</hackBaseline>
        <distortionK1>0.0</distortionK1>
        <distortionK2>0.0</distortionK2>
        <distortionK3>0.0</distortionK3>
        <distortionT1>0.0</distortionT1>
        <distortionT2>0.0</distortionT2>
      </plugin>
    </sensor>
  </gazebo>

  <gazebo reference="scan_link">

    <material>Gazebo/Blue</material>

	    <sensor name="head_hokuyo_sensor" type="ray">

	      <pose>0.05 0 0 0 0 0</pose>

	      <visualize>true</visualize>

	      <update_rate>40</update_rate>

	      <ray>

	        <scan>

	          <horizontal>

	            <samples>720</samples>

	            <resolution>1</resolution>

	            <min_angle>-0.0349066</min_angle>

	            <max_angle>0.0349066</max_angle>

	          </horizontal>

	        </scan>

	        <range>

	          <min>0.10</min>

	          <max>10.0</max>

	          <resolution>0.001</resolution>

	        </range>

	      </ray>

	      <plugin filename="libgazebo_ros_laser.so" name="gazebo_ros_head_hokuyo_controller">

	        <topicName>/scan</topicName>

	        <frameName>scan_link</frameName>

	      </plugin>

	    </sensor>

  	</gazebo>

</robot>
